#VRML_SIM R2023a utf8

EXTERNPROTO "https://raw.githubusercontent.com/cyberbotics/webots/R2023a/projects/objects/backgrounds/protos/TexturedBackground.proto"
EXTERNPROTO "https://raw.githubusercontent.com/cyberbotics/webots/R2023a/projects/objects/backgrounds/protos/TexturedBackgroundLight.proto"
EXTERNPROTO "https://raw.githubusercontent.com/cyberbotics/webots/R2023a/projects/objects/floors/protos/Floor.proto"

WorldInfo {
}
Viewpoint {
  orientation -0.2497556143644588 -0.09193932917231215 0.963934278280826 3.8235655164429216
  position 3.2232615409633305 2.624539261123539 2.445458406816127
}
TexturedBackground {
}
TexturedBackgroundLight {
}
Floor {
  size 2 4
  tileSize 10 2
}
Robot {
  translation 0 0 0.07
  children [
    DEF RearRightCorner Transform {
      translation -0.05 0.075 0.047
      scale 0.5 1.4 0.1
      children [
        Shape {
          appearance PBRAppearance {
            baseColor 0.666667 1 0
            roughness 1
            metalness 0
          }
          geometry Cone {
            bottomRadius 0.05
            height 0.6
            subdivision 100
          }
        }
      ]
    }
    DEF RearLeftCorner Transform {
      translation 0.05 0.075 0.047
      scale 0.5 1.4 0.1
      children [
        Shape {
          appearance PBRAppearance {
            baseColor 0.666667 1 0
            roughness 1
            metalness 0
          }
          geometry Cone {
            bottomRadius 0.05
            height 0.6
            subdivision 100
          }
        }
      ]
    }
    DEF FrontRightCorner Transform {
      translation -0.05 -0.075 0.058
      scale 0.4 1.8 0.14
      children [
        Shape {
          appearance PBRAppearance {
            baseColor 0.666667 1 0
            roughness 1
            metalness 0
          }
          geometry Cone {
            bottomRadius 0.05
            height 0.3
            subdivision 100
          }
        }
      ]
    }
    DEF FrontLeftCorner Transform {
      translation 0.05 -0.075 0.058
      scale 0.4 1.8 0.14
      children [
        Shape {
          appearance PBRAppearance {
            baseColor 0.666667 1 0
            roughness 1
            metalness 0
          }
          geometry Cone {
            bottomRadius 0.05
            height 0.3
            subdivision 100
          }
        }
      ]
    }
    DEF SpoilerSupportLeft Transform {
      translation 0.06 0.15 0.04
      rotation -0.3517778206671053 -0.849265971929861 0.3936999794370465 1.7177703061004252
      children [
        Shape {
          appearance PBRAppearance {
            baseColor 0.666667 1 0
            roughness 1
            metalness 0
          }
          geometry Box {
            size 0.06 0.015 0.01
          }
        }
      ]
    }
    DEF SpoilerSupportRight Transform {
      translation -0.06 0.15 0.04
      rotation -0.3517778206671053 -0.849265971929861 0.3936999794370465 1.7177703061004252
      children [
        Shape {
          appearance PBRAppearance {
            baseColor 0.666667 1 0
            roughness 1
            metalness 0
          }
          geometry Box {
            size 0.06 0.015 0.01
          }
        }
      ]
    }
    DEF Spoiler Transform {
      translation 0 0.175 0.06
      children [
        Shape {
          appearance PBRAppearance {
            baseColor 0.666667 1 0
            roughness 1
            metalness 0
          }
          geometry Box {
            size 0.2 0.04 0.0125
          }
        }
      ]
    }
    DEF FrontGlass Transform {
      translation 0 -0.112 0.047
      rotation 1 0 0 -1.18
      scale 1 1 1.4
      children [
        Shape {
          appearance PBRAppearance {
          }
          geometry Box {
            size 0.099 0.03 0.07
          }
        }
      ]
    }
    DEF RightGlass Transform {
      translation -0.013 0 0.038
      rotation 0 1 0 -1.1780996938995747
      scale 0.5 1.5 1
      children [
        Shape {
          appearance PBRAppearance {
          }
          geometry Box {
            size 0.1 0.1 0.1
          }
        }
      ]
    }
    DEF LeftGlass Transform {
      translation 0.013 0 0.038
      rotation 0 1 0 -1.9634953071795866
      scale 0.5 1.5 1
      children [
        Shape {
          appearance PBRAppearance {
          }
          geometry Box {
            size 0.1 0.1 0.1
          }
        }
      ]
    }
    DEF RearGlass Transform {
      translation 0 0.0894639 0.0407762
      rotation -1 0 0 -0.8590953071795866
      scale 1 1.3 1.05
      children [
        Shape {
          appearance PBRAppearance {
          }
          geometry Box {
            size 0.099 0.03 0.07
          }
        }
      ]
    }
    DEF Frame Transform {
      translation 0 0 0.03
      scale 1 1.5 1
      children [
        Shape {
          appearance PBRAppearance {
            baseColor 0 0.333333 0
            roughness 1
            metalness 0
          }
          geometry Box {
            size 0.1 0.1 0.1
          }
        }
      ]
    }
    DEF FrontBumper Transform {
      translation 0 -0.09 0.004
      rotation 0 1 0 -1.5707953071795862
      scale 0.65 1.5 0.334
      children [
        Shape {
          appearance PBRAppearance {
            baseColor 0 0.333333 0
            roughness 1
            metalness 0
          }
          geometry Cylinder {
            height 0.45
            radius 0.076
          }
        }
      ]
    }
    DEF RearBumper Transform {
      translation 0 0.145 0.003
      rotation 0 1 0 -1.5707953071795862
      scale 1.4 0.7 1
      children [
        Shape {
          appearance PBRAppearance {
            baseColor 0 0.333333 0
            roughness 1
            metalness 0
          }
          geometry Cylinder {
            height 0.15
            radius 0.03
          }
        }
      ]
    }
    Compass {
    }
    GPS {
    }
    DEF MainBody Solid {
      children [
        DEF BodyShape Shape {
          appearance PBRAppearance {
            baseColor 0 0.333333 0
            roughness 1
            metalness 0
          }
          geometry Box {
            size 0.15 0.3 0.075
          }
        }
      ]
      boundingObject USE BodyShape
      physics Physics {
      }
    }
    DEF FrontLeft HingeJoint {
      jointParameters HingeJointParameters {
        anchor 0.09 -0.1 -0.02
      }
      device [
        RotationalMotor {
          name "wheel_fl"
          maxVelocity 100
          maxTorque 100
        }
      ]
      endPoint Solid {
        translation 0.09 -0.1 -0.02
        rotation -1.4018223718727404e-06 0.9999999999980349 -1.4018275210632897e-06 1.5708000000019655
        children [
          DEF wheel Shape {
            appearance PBRAppearance {
              baseColor 0 0 0
              roughness 1
              metalness 0
            }
            geometry Cylinder {
              height 0.03
              radius 0.05
            }
          }
        ]
        name "solid(2)"
        boundingObject USE wheel
        physics Physics {
        }
      }
    }
    DEF FrontRight HingeJoint {
      jointParameters HingeJointParameters {
        anchor -0.09 -0.1 -0.02
      }
      device [
        RotationalMotor {
          name "wheel_fr"
          maxVelocity 100
          maxTorque 100
        }
      ]
      endPoint Solid {
        translation -0.09 -0.1 -0.02
        rotation -1.4018223718727404e-06 0.9999999999980349 -1.4018275210632897e-06 1.5708000000019655
        children [
          DEF wheel Shape {
            appearance PBRAppearance {
              baseColor 0 0 0
              roughness 1
              metalness 0
            }
            geometry Cylinder {
              height 0.03
              radius 0.05
            }
          }
        ]
        name "solid(4)"
        boundingObject USE wheel
        physics Physics {
        }
      }
    }
    DEF RearRight HingeJoint {
      jointParameters HingeJointParameters {
        anchor -0.09 0.1 -0.02
      }
      endPoint Solid {
        translation -0.09 0.1 -0.02
        rotation -1.4018223718727404e-06 0.9999999999980349 -1.4018275210632897e-06 1.5708000000019655
        children [
          DEF wheel Shape {
            appearance PBRAppearance {
              baseColor 0 0 0
              roughness 1
              metalness 0
            }
            geometry Cylinder {
              height 0.03
              radius 0.05
            }
          }
        ]
        name "solid(1)"
        boundingObject USE wheel
        physics Physics {
        }
      }
    }
    DEF RearLeft HingeJoint {
      jointParameters HingeJointParameters {
        anchor 0.09 0.1 -0.02
      }
      endPoint Solid {
        translation 0.09 0.1 -0.02
        rotation -1.4018223718727404e-06 0.9999999999980349 -1.4018275210632897e-06 1.5708000000019655
        children [
          DEF wheel Shape {
            appearance PBRAppearance {
              baseColor 0 0 0
              roughness 1
              metalness 0
            }
            geometry Cylinder {
              height 0.03
              radius 0.05
            }
          }
        ]
        name "solid(3)"
        boundingObject USE wheel
        physics Physics {
        }
      }
    }
  ]
  boundingObject DEF BodyPhysics Shape {
    geometry Box {
      size 0.22 0.4 0.13
    }
  }
  physics Physics {
  }
  controller "pls_controller"
}
