#VRML_SIM R2023a utf8

EXTERNPROTO "https://raw.githubusercontent.com/cyberbotics/webots/R2023a/projects/objects/backgrounds/protos/TexturedBackground.proto"
EXTERNPROTO "https://raw.githubusercontent.com/cyberbotics/webots/R2023a/projects/objects/backgrounds/protos/TexturedBackgroundLight.proto"
EXTERNPROTO "https://raw.githubusercontent.com/cyberbotics/webots/R2023a/projects/objects/floors/protos/Floor.proto"
EXTERNPROTO "https://raw.githubusercontent.com/cyberbotics/webots/R2023a/projects/objects/apartment_structure/protos/Wall.proto"

WorldInfo {
}
Viewpoint {
  orientation -0.24897897219375315 0.38607318132042123 0.8882324977563427 1.263778637100758
  position -4.1408914531190355 -6.726511029977257 5.22884978258895
  follow "robot"
  followType "Mounted Shot"
}
TexturedBackground {
}
TexturedBackgroundLight {
}
Floor {
  size 7 8
  tileSize 10 2
}
Robot {
  translation -0.5324665180357533 1.895507841019098 0.0690984389815688
  rotation 0.0006303756979471681 0.0007083355321239233 0.9999995504435256 3.1409030179091593
  children [
    DEF RearRightCorner Transform {
      translation -0.05 0.075 0.047
      scale 0.5 1.4 0.1
      children [
        Shape {
          appearance PBRAppearance {
            baseColor 0.666667 1 0
            roughness 1
            metalness 0
          }
          geometry Cone {
            bottomRadius 0.05
            height 0.6
            subdivision 100
          }
        }
      ]
    }
    DEF RearLeftCorner Transform {
      translation 0.05 0.075 0.047
      scale 0.5 1.4 0.1
      children [
        Shape {
          appearance PBRAppearance {
            baseColor 0.666667 1 0
            roughness 1
            metalness 0
          }
          geometry Cone {
            bottomRadius 0.05
            height 0.6
            subdivision 100
          }
        }
      ]
    }
    DEF FrontRightCorner Transform {
      translation -0.05 -0.075 0.058
      scale 0.4 1.8 0.14
      children [
        Shape {
          appearance PBRAppearance {
            baseColor 0.666667 1 0
            roughness 1
            metalness 0
          }
          geometry Cone {
            bottomRadius 0.05
            height 0.3
            subdivision 100
          }
        }
      ]
    }
    DEF FrontLeftCorner Transform {
      translation 0.05 -0.075 0.058
      scale 0.4 1.8 0.14
      children [
        Shape {
          appearance PBRAppearance {
            baseColor 0.666667 1 0
            roughness 1
            metalness 0
          }
          geometry Cone {
            bottomRadius 0.05
            height 0.3
            subdivision 100
          }
        }
      ]
    }
    DEF SpoilerSupportLeft Transform {
      translation 0.06 0.15 0.04
      rotation -0.3517778206671053 -0.849265971929861 0.3936999794370465 1.7177703061004252
      children [
        Shape {
          appearance PBRAppearance {
            baseColor 0.666667 1 0
            roughness 1
            metalness 0
          }
          geometry Box {
            size 0.06 0.015 0.01
          }
        }
      ]
    }
    DEF SpoilerSupportRight Transform {
      translation -0.06 0.15 0.04
      rotation -0.3517778206671053 -0.849265971929861 0.3936999794370465 1.7177703061004252
      children [
        Shape {
          appearance PBRAppearance {
            baseColor 0.666667 1 0
            roughness 1
            metalness 0
          }
          geometry Box {
            size 0.06 0.015 0.01
          }
        }
      ]
    }
    DEF Spoiler Transform {
      translation 0 0.175 0.06
      children [
        Shape {
          appearance PBRAppearance {
            baseColor 0.666667 1 0
            roughness 1
            metalness 0
          }
          geometry Box {
            size 0.15 0.04 0.0125
          }
        }
      ]
    }
    DEF FrontGlass Transform {
      translation 0 -0.112 0.047
      rotation 1 0 0 -1.18
      scale 1 1 1.4
      children [
        Shape {
          appearance PBRAppearance {
          }
          geometry Box {
            size 0.099 0.03 0.07
          }
        }
      ]
    }
    DEF RightGlass Transform {
      translation -0.013 0 0.038
      rotation 0 1 0 -1.1780996938995747
      scale 0.5 1.5 1
      children [
        Shape {
          appearance PBRAppearance {
          }
          geometry Box {
            size 0.1 0.1 0.1
          }
        }
      ]
    }
    DEF LeftGlass Transform {
      translation 0.013 0 0.038
      rotation 0 1 0 -1.9634953071795866
      scale 0.5 1.5 1
      children [
        Shape {
          appearance PBRAppearance {
          }
          geometry Box {
            size 0.1 0.1 0.1
          }
        }
      ]
    }
    DEF RearGlass Transform {
      translation 0 0.0894639 0.0407762
      rotation -1 0 0 -0.8590953071795866
      scale 1 1.3 1.05
      children [
        Shape {
          appearance PBRAppearance {
          }
          geometry Box {
            size 0.099 0.03 0.07
          }
        }
      ]
    }
    DEF Frame Transform {
      translation 0 0 0.03
      scale 1 1.5 1
      children [
        Shape {
          appearance PBRAppearance {
            baseColor 0 0.333333 0
            roughness 1
            metalness 0
          }
          geometry Box {
            size 0.1 0.1 0.1
          }
        }
      ]
    }
    DEF FrontBumper Transform {
      translation 0 -0.09 0.004
      rotation 0 1 0 -1.5707953071795862
      scale 0.65 1.5 0.334
      children [
        Shape {
          appearance PBRAppearance {
            baseColor 0 0.333333 0
            roughness 1
            metalness 0
          }
          geometry Cylinder {
            height 0.45
            radius 0.076
          }
        }
      ]
    }
    DEF RearBumper Transform {
      translation 0 0.145 0.003
      rotation 0 1 0 -1.5707953071795862
      scale 1.4 0.7 1
      children [
        Shape {
          appearance PBRAppearance {
            baseColor 0 0.333333 0
            roughness 1
            metalness 0
          }
          geometry Cylinder {
            height 0.15
            radius 0.03
          }
        }
      ]
    }
    Compass {
    }
    GPS {
    }
    DEF MainBody Solid {
      children [
        DEF BodyShape Shape {
          appearance PBRAppearance {
            baseColor 0 0.333333 0
            roughness 1
            metalness 0
          }
          geometry Box {
            size 0.15 0.3 0.075
          }
        }
      ]
    }
    DEF FrontLeft HingeJoint {
      jointParameters HingeJointParameters {
        position 113.65335837375682
        anchor 0.1 -0.1 -0.02
      }
      device [
        RotationalMotor {
          name "wheel_fl"
          maxVelocity 100
          maxTorque 100
        }
      ]
      endPoint Solid {
        translation 0.10009417039362967 -0.09992740781698134 -0.02000675308508919
        rotation 0.6771173177040481 0.2879618204712992 0.6771928292710505 2.576229348644526
        children [
          DEF wheel Shape {
            appearance PBRAppearance {
              baseColor 0 0 0
              roughness 1
              metalness 0
            }
            geometry Cylinder {
              height 0.03
              radius 0.05
            }
          }
        ]
        name "solid(2)"
        boundingObject USE wheel
        physics Physics {
        }
      }
    }
    DEF FrontRight HingeJoint {
      jointParameters HingeJointParameters {
        position -106.61349050574269
        anchor -0.1 -0.1 -0.02
      }
      device [
        RotationalMotor {
          name "wheel_fr"
          maxVelocity 100
          maxTorque 100
        }
      ]
      endPoint Solid {
        translation -0.09999578206532267 -0.09995885922494097 -0.020016761708036134
        rotation 0.5800428155790042 -0.5728991620594555 0.5790827939135779 4.178463044597601
        children [
          DEF wheel Shape {
            appearance PBRAppearance {
              baseColor 0 0 0
              roughness 1
              metalness 0
            }
            geometry Cylinder {
              height 0.03
              radius 0.05
            }
          }
        ]
        name "solid(4)"
        boundingObject USE wheel
        physics Physics {
          density -1
          mass 1
        }
      }
    }
    DEF RearRight HingeJoint {
      jointParameters HingeJointParameters {
        position 35.60097863920856
        anchor -0.1 0.1 -0.02
        dampingConstant 0.01
      }
      endPoint Solid {
        translation -0.1001183061548645 0.09998766070150417 -0.020035758082887725
        rotation 0.29900589690187546 0.9059038722067795 0.29988939284120764 1.6663100269518805
        children [
          DEF wheel Shape {
            appearance PBRAppearance {
              baseColor 0 0 0
              roughness 1
              metalness 0
            }
            geometry Cylinder {
              height 0.03
              radius 0.05
            }
          }
        ]
        name "solid(1)"
        boundingObject USE wheel
        physics Physics {
          density -1
          mass 1
        }
      }
    }
    DEF RearLeft HingeJoint {
      jointParameters HingeJointParameters {
        position 46.918153660824586
        anchor 0.1 0.1 -0.02
        dampingConstant 0.01
      }
      endPoint Solid {
        translation 0.10001798743533541 0.099922861052039 -0.019972916994213104
        rotation 0.5885333722774858 -0.5547466200788044 0.5881195943231556 4.158293690709511
        children [
          DEF wheel Shape {
            appearance PBRAppearance {
              baseColor 0 0 0
              roughness 1
              metalness 0
            }
            geometry Cylinder {
              height 0.03
              radius 0.05
            }
          }
        ]
        name "solid(3)"
        boundingObject USE wheel
        physics Physics {
          density -1
          mass 1
        }
      }
    }
  ]
  boundingObject DEF Physic Transform {
    translation 0 0 0.01
    rotation 1 0 0 4.692820414042842e-06
    children [
      Shape {
        geometry Box {
          size 0.15 0.425 0.13
        }
      }
    ]
  }
  physics Physics {
    density -1
    mass 1
  }
  controller "pls_controller"
}
Wall {
}
Wall {
  name "wall(1)"
}
Wall {
  name "wall(2)"
}
Wall {
  name "wall(3)"
}
Wall {
  name "wall(4)"
}
Wall {
  name "wall(5)"
}
Wall {
  name "wall(6)"
}
Wall {
  name "wall(7)"
}
Wall {
  name "wall(8)"
}
Wall {
  name "wall(9)"
}
Wall {
  name "wall(10)"
}
Wall {
  name "wall(11)"
}
Wall {
  name "wall(12)"
}
Wall {
  name "wall(13)"
}
Wall {
  name "wall(14)"
}
Wall {
  name "wall(15)"
}
Wall {
  name "wall(16)"
}
