#VRML_SIM R2023a utf8

EXTERNPROTO "https://raw.githubusercontent.com/cyberbotics/webots/R2023a/projects/objects/floors/protos/RectangleArena.proto"
EXTERNPROTO "https://raw.githubusercontent.com/cyberbotics/webots/R2023a/projects/objects/backgrounds/protos/TexturedBackground.proto"
EXTERNPROTO "https://raw.githubusercontent.com/cyberbotics/webots/R2023a/projects/objects/backgrounds/protos/TexturedBackgroundLight.proto"

WorldInfo {
  coordinateSystem "NUE"
}
Viewpoint {
  orientation 0.6615087511369863 -0.06910377800880818 0.7467468379806466 4.701471271011325
  position -0.2625459499498701 3.9745262570809077 0.2804184705750522
}
TexturedBackground {
}
TexturedBackgroundLight {
}
RectangleArena {
  translation 2.5 0 2.5
  rotation 1 0 0 -1.5707953071795862
  floorSize 10 10
  floorTileSize 10 20
}
Robot {
  translation 2.5 0.04 2.5
  children [
    Transform {
      translation 0.02 0.0275 0.02
      rotation -1 0 0 1.5707963267948966
      scale 0.5 0.5 0.5
      children [
        Shape {
          appearance PBRAppearance {
            baseColor 0.309804 0.0784314 1
            roughness 1
            metalness 0
          }
          geometry Cone {
            bottomRadius 0.0375
            height 0.04
            subdivision 64
          }
        }
      ]
    }
    Transform {
      translation 0.02 0.0275 -0.02
      rotation -1 0 0 1.5707963267948966
      scale 0.5 0.5 0.5
      children [
        Shape {
          appearance PBRAppearance {
            baseColor 0.309804 0.0784314 1
            roughness 1
            metalness 0
          }
          geometry Cone {
            bottomRadius 0.0375
            height 0.04
            subdivision 64
          }
        }
      ]
    }
    Transform {
      translation -0.02 0.0275 -0.02
      rotation -1 0 0 1.5707963267948966
      scale 0.5 0.5 0.5
      children [
        Shape {
          appearance PBRAppearance {
            baseColor 0.309804 0.0784314 1
            roughness 1
            metalness 0
          }
          geometry Cone {
            bottomRadius 0.0375
            height 0.04
            subdivision 64
          }
        }
      ]
    }
    Transform {
      translation -0.02 0.0275 0.02
      rotation -1 0 0 1.5707963267948966
      scale 0.5 0.5 0.5
      children [
        Shape {
          appearance PBRAppearance {
            baseColor 0.309804 0.0784314 1
            roughness 1
            metalness 0
          }
          geometry Cone {
            bottomRadius 0.0375
            height 0.04
            subdivision 64
          }
        }
      ]
    }
    Transform {
      translation 0 0.014 -0.015
      rotation 1 0 0 -0.785395307179586
      scale 0.375 0.4 0.3
      children [
        Shape {
          appearance PBRAppearance {
            baseColor 0.807843 0.835294 1
            roughness 1
            metalness 0
          }
          geometry Box {
            size 0.1 0.1 0.1
          }
        }
      ]
    }
    Transform {
      translation 0 0.0135 0.0235
      rotation 1 0 0 -0.785395307179586
      scale 0.375 0.4 0.3
      children [
        Shape {
          appearance PBRAppearance {
            baseColor 0.807843 0.835294 1
            roughness 1
            metalness 0
          }
          geometry Box {
            size 0.1 0.1 0.1
          }
        }
      ]
    }
    Transform {
      translation 0.023 0.02 0
      rotation 0 0 1 2.35619
      scale 0.3 0.2 0.375
      children [
        Shape {
          appearance PBRAppearance {
            baseColor 0.807843 0.835294 1
            roughness 1
            metalness 0
          }
          geometry Box {
            size 0.1 0.1 0.1
          }
        }
      ]
    }
    Transform {
      translation -0.023 0.02 0
      rotation 0 0 1 0.785398
      scale 0.3 0.2 0.375
      children [
        Shape {
          appearance PBRAppearance {
            baseColor 0.807843 0.835294 1
            roughness 1
            metalness 0
          }
          geometry Box {
            size 0.1 0.1 0.1
          }
        }
      ]
    }
    Transform {
      translation 0 0.027 0
      scale 0.4 0.235 0.4
      children [
        Shape {
          appearance PBRAppearance {
            baseColor 0.309804 0.0784314 1
            roughness 1
            metalness 0
          }
          geometry Box {
            size 0.1 0.1 0.1
          }
        }
      ]
    }
    Transform {
      translation -3.17278e-09 0.01 -0.075
      rotation 0.577656895078166 0.5771968951617173 -0.5771968951617173 -2.093935307179586
      scale 0.3 0.65 0.9
      children [
        Shape {
          appearance PBRAppearance {
            baseColor 0.309804 0.0784314 1
            roughness 1
            metalness 0
          }
          geometry Cylinder {
            height 0.1
            radius 0.05
          }
        }
      ]
    }
    Transform {
      translation 0 0 0.09
      rotation -1 0 0 1.5707963267948966
      scale 1 0.3 0.2
      children [
        Shape {
          appearance PBRAppearance {
            baseColor 0.309804 0.0784314 1
            roughness 1
            metalness 0
          }
          geometry Cylinder {
            height 0.1
            radius 0.05
          }
        }
      ]
    }
    Transform {
      scale 1 0.35 1.8
      children [
        Shape {
          appearance PBRAppearance {
            baseColor 0.309804 0.0784314 1
            roughness 1
            metalness 0
          }
          geometry Box {
            size 0.1 0.1 0.1
          }
        }
      ]
    }
    Transform {
      translation 0.04 0.03 -0.1
      rotation 1 0 0 -0.523595307179586
      scale 0.1 0.25 0.1
      children [
        Shape {
          appearance PBRAppearance {
            baseColor 1 0.721569 0.0745098
            roughness 1
            metalness 0
          }
          geometry Box {
            size 0.1 0.1 0.1
          }
        }
      ]
    }
    Transform {
      translation -0.04 0.03 -0.1
      rotation 1 0 0 -0.523595307179586
      scale 0.1 0.25 0.1
      children [
        Shape {
          appearance PBRAppearance {
            baseColor 1 0.721569 0.0745098
            roughness 1
            metalness 0
          }
          geometry Box {
            size 0.1 0.1 0.1
          }
        }
      ]
    }
    Transform {
      translation 0 0.041 -0.11
      scale 1.1 0.05 0.3
      children [
        Shape {
          appearance PBRAppearance {
            baseColor 1 0.721569 0.0745098
            roughness 1
            metalness 0
          }
          geometry Box {
            size 0.1 0.1 0.1
          }
        }
      ]
    }
    DEF Body Group {
      children [
        Shape {
          appearance PBRAppearance {
            transparency 1
          }
          geometry Box {
            size 0.1 0.05 0.2
          }
        }
      ]
    }
    GPS {
    }
    Compass {
    }
    HingeJoint {
      jointParameters HingeJointParameters {
        anchor 0.06 0 0.05
      }
      device [
        RotationalMotor {
          name "wheel_fl"
          maxVelocity 100
          maxTorque 100
        }
      ]
      endPoint Solid {
        translation 0.06 0 0.05
        rotation 7.846886473750622e-17 1 0 1.571707932926737
        children [
          DEF wheel Shape {
            appearance PBRAppearance {
              baseColor 0 0 0
              roughness 1
              metalness 0
            }
            geometry Cylinder {
              height 0.02
              radius 0.04
            }
          }
        ]
        name "solid(1)"
        boundingObject USE wheel
        physics Physics {
        }
      }
    }
    DistanceSensor {
      translation 0.045 0 0.1
      rotation 0 -1 0 0.785406
      children [
        Shape {
          appearance PBRAppearance {
            baseColor 0 1 1
            roughness 1
            metalness 0
          }
          geometry Box {
            size 0.01 0.01 0.01
          }
        }
      ]
      name "ds_left"
      lookupTable [
        0 0 0
        0.2 1000 0
      ]
      type "laser"
    }
    DistanceSensor {
      translation -0.045 0 0.1
      rotation 0 1 0 -2.3561953071795863
      children [
        Shape {
          appearance PBRAppearance {
            baseColor 0 1 1
            roughness 1
            metalness 0
          }
          geometry Box {
            size 0.01 0.01 0.01
          }
        }
      ]
      name "ds_right"
      lookupTable [
        0 0 0
        0.2 1000 0
      ]
      type "laser"
    }
    DistanceSensor {
      translation 0 0 0.1
      rotation 0 1 0 -1.57
      children [
        Shape {
          appearance PBRAppearance {
            baseColor 0 1 1
            roughness 1
            metalness 0
          }
          geometry Box {
            size 0.01 0.01 0.01
          }
        }
      ]
      name "ds_mid"
      lookupTable [
        0 0 0
        0.2 1000 0
      ]
      type "laser"
    }
    HingeJoint {
      jointParameters HingeJointParameters {
        anchor 0.06 0 -0.05
      }
      endPoint Solid {
        translation 0.06 0 -0.05
        rotation -3.923443192396346e-17 1 3.923443192396346e-17 1.57170795562085
        children [
          DEF wheel Shape {
            appearance PBRAppearance {
              baseColor 0 0 0
              roughness 1
              metalness 0
            }
            geometry Cylinder {
              height 0.02
              radius 0.04
            }
          }
        ]
        name "solid(2)"
        boundingObject USE wheel
        physics Physics {
        }
      }
    }
    HingeJoint {
      jointParameters HingeJointParameters {
        anchor -0.06 0 0.05
      }
      device [
        RotationalMotor {
          name "wheel_fr"
          maxVelocity 100
          maxTorque 100
        }
      ]
      endPoint Solid {
        translation -0.06 0 0.05
        rotation -5.88614467583233e-17 1 7.848192901109774e-17 1.571374732696555
        children [
          DEF wheel Shape {
            appearance PBRAppearance {
              baseColor 0 0 0
              roughness 1
              metalness 0
            }
            geometry Cylinder {
              height 0.02
              radius 0.04
            }
          }
        ]
        name "solid(3)"
        boundingObject USE wheel
        physics Physics {
        }
      }
    }
    HingeJoint {
      jointParameters HingeJointParameters {
        anchor -0.06 0 -0.05
      }
      endPoint Solid {
        translation -0.06 0 -0.05
        rotation 3.924096452972608e-17 1 9.81024113243152e-17 1.571374731463599
        children [
          DEF wheel Shape {
            appearance PBRAppearance {
              baseColor 0 0 0
              roughness 1
              metalness 0
            }
            geometry Cylinder {
              height 0.02
              radius 0.04
            }
          }
        ]
        name "solid(4)"
        boundingObject USE wheel
        physics Physics {
        }
      }
    }
  ]
  boundingObject USE Body
  physics Physics {
  }
  controller "robot_controller"
}
