#VRML_SIM R2023a utf8

EXTERNPROTO "https://raw.githubusercontent.com/cyberbotics/webots/R2023a/projects/objects/backgrounds/protos/TexturedBackground.proto"
EXTERNPROTO "https://raw.githubusercontent.com/cyberbotics/webots/R2023a/projects/objects/backgrounds/protos/TexturedBackgroundLight.proto"
EXTERNPROTO "https://raw.githubusercontent.com/cyberbotics/webots/R2023a/projects/objects/floors/protos/Floor.proto"
EXTERNPROTO "https://raw.githubusercontent.com/cyberbotics/webots/R2023a/projects/appearances/protos/Parquetry.proto"

WorldInfo {
  coordinateSystem "NUE"
}
Viewpoint {
  orientation -0.9535202535073448 0.17235700843808452 -0.24716833897884902 1.607697641379199
  position -4.270108165522343 3.2817463800007616 4.106293522318148
}
TexturedBackground {
}
TexturedBackgroundLight {
}
Floor {
  translation 3 -0.001 5
  rotation 1 0 0 -1.5707953071795862
  name "0"
  size 2 2
  tileSize 2 4
  appearance Parquetry {
    type "chequered"
    colorOverride 0.7 0.9 0.7
  }
}
Floor {
  translation 3 -0.001 3
  rotation 1 0 0 -1.5707953071795862
  name "1"
  size 2 2
  tileSize 2 2
  appearance Parquetry {
    type "chequered"
    colorOverride 0.7 0.9 0.7
  }
}
Floor {
  translation 3 -0.001 7
  rotation 0.5773502691896258 0.5773502691896258 0.5773502691896258 -2.0943896938995747
  name "2"
  size 2 2
  tileSize 2 2
  appearance Parquetry {
    type "chequered"
    colorOverride 0.7 0.9 0.7
  }
}
Floor {
  translation 5 -0.001 3
  rotation 0 0.7071067811865475 0.7071067811865475 -3.141592653589793
  name "3"
  size 2 2
  tileSize 4 2
  appearance Parquetry {
    type "chequered"
    colorOverride 0.7 0.9 0.7
  }
}
Floor {
  translation 5 -0.001 7
  rotation 0.5773502691896258 -0.5773502691896258 -0.5773502691896258 -2.094399693899575
  name "4"
  size 2 2
  tileSize 2 4
  appearance Parquetry {
    type "chequered"
    colorOverride 0.7 0.9 0.7
  }
}
Floor {
  translation 3 -0.001 1
  rotation 0.5773502691896258 -0.5773502691896258 -0.5773502691896258 -2.0944049989208384
  name "5"
  size 2 2
  tileSize 4 2
  appearance Parquetry {
    type "chequered"
    colorOverride 0.7 0.9 0.7
  }
}
Floor {
  translation 3 -0.001 9
  rotation 0.5773502691896258 -0.5773502691896258 -0.5773502691896258 -2.0944049989208384
  name "6"
  size 2 2
  tileSize 4 2
  appearance Parquetry {
    type "chequered"
    colorOverride 0.7 0.9 0.7
  }
}
Floor {
  translation 1 -0.001 3
  rotation 0.5773502691896258 -0.5773502691896258 -0.5773502691896258 -2.094399693899575
  name "7"
  size 2 2
  tileSize 2 4
  appearance Parquetry {
    type "chequered"
    colorOverride 0.7 0.9 0.7
  }
}
Floor {
  translation 1 -0.001 7
  rotation 0 0.7071067811865475 0.7071067811865475 -3.141592653589793
  name "8"
  size 2 2
  tileSize 4 2
  appearance Parquetry {
    type "chequered"
    colorOverride 0.7 0.9 0.7
  }
}
Robot {
  translation 3 0.045 5
  children [
    Transform {
      translation 0.02 0.0275 0.02
      rotation -1 0 0 1.5707963267948966
      scale 0.5 0.5 0.5
      children [
        Shape {
          appearance PBRAppearance {
            baseColor 0.309804 0.0784314 1
            roughness 1
            metalness 0
          }
          geometry Cone {
            bottomRadius 0.0375
            height 0.04
            subdivision 64
          }
        }
      ]
    }
    Transform {
      translation 0.02 0.0275 -0.02
      rotation -1 0 0 1.5707963267948966
      scale 0.5 0.5 0.5
      children [
        Shape {
          appearance PBRAppearance {
            baseColor 0.309804 0.0784314 1
            roughness 1
            metalness 0
          }
          geometry Cone {
            bottomRadius 0.0375
            height 0.04
            subdivision 64
          }
        }
      ]
    }
    Transform {
      translation -0.02 0.0275 -0.02
      rotation -1 0 0 1.5707963267948966
      scale 0.5 0.5 0.5
      children [
        Shape {
          appearance PBRAppearance {
            baseColor 0.309804 0.0784314 1
            roughness 1
            metalness 0
          }
          geometry Cone {
            bottomRadius 0.0375
            height 0.04
            subdivision 64
          }
        }
      ]
    }
    Transform {
      translation -0.02 0.0275 0.02
      rotation -1 0 0 1.5707963267948966
      scale 0.5 0.5 0.5
      children [
        Shape {
          appearance PBRAppearance {
            baseColor 0.309804 0.0784314 1
            roughness 1
            metalness 0
          }
          geometry Cone {
            bottomRadius 0.0375
            height 0.04
            subdivision 64
          }
        }
      ]
    }
    Transform {
      translation 0 0.014 -0.015
      rotation 1 0 0 -0.785395307179586
      scale 0.375 0.4 0.3
      children [
        Shape {
          appearance PBRAppearance {
            baseColor 0.807843 0.835294 1
            roughness 1
            metalness 0
          }
          geometry Box {
            size 0.1 0.1 0.1
          }
        }
      ]
    }
    Transform {
      translation 0 0.0135 0.0235
      rotation 1 0 0 -0.785395307179586
      scale 0.375 0.4 0.3
      children [
        Shape {
          appearance PBRAppearance {
            baseColor 0.807843 0.835294 1
            roughness 1
            metalness 0
          }
          geometry Box {
            size 0.1 0.1 0.1
          }
        }
      ]
    }
    Transform {
      translation 0.023 0.02 0
      rotation 0 0 1 2.35619
      scale 0.3 0.2 0.375
      children [
        Shape {
          appearance PBRAppearance {
            baseColor 0.807843 0.835294 1
            roughness 1
            metalness 0
          }
          geometry Box {
            size 0.1 0.1 0.1
          }
        }
      ]
    }
    Transform {
      translation -0.023 0.02 0
      rotation 0 0 1 0.785398
      scale 0.3 0.2 0.375
      children [
        Shape {
          appearance PBRAppearance {
            baseColor 0.807843 0.835294 1
            roughness 1
            metalness 0
          }
          geometry Box {
            size 0.1 0.1 0.1
          }
        }
      ]
    }
    Transform {
      translation 0 0.027 0
      scale 0.4 0.235 0.4
      children [
        Shape {
          appearance PBRAppearance {
            baseColor 0.309804 0.0784314 1
            roughness 1
            metalness 0
          }
          geometry Box {
            size 0.1 0.1 0.1
          }
        }
      ]
    }
    Transform {
      translation -3.17278e-09 0.01 -0.075
      rotation 0.577656895078166 0.5771968951617173 -0.5771968951617173 -2.093935307179586
      scale 0.3 0.65 0.9
      children [
        Shape {
          appearance PBRAppearance {
            baseColor 0.309804 0.0784314 1
            roughness 1
            metalness 0
          }
          geometry Cylinder {
            height 0.1
            radius 0.05
          }
        }
      ]
    }
    Transform {
      translation 0 0 0.09
      rotation -1 0 0 1.5707963267948966
      scale 1 0.3 0.2
      children [
        Shape {
          appearance PBRAppearance {
            baseColor 0.309804 0.0784314 1
            roughness 1
            metalness 0
          }
          geometry Cylinder {
            height 0.1
            radius 0.05
          }
        }
      ]
    }
    Transform {
      scale 1 0.35 1.8
      children [
        Shape {
          appearance PBRAppearance {
            baseColor 0.309804 0.0784314 1
            roughness 1
            metalness 0
          }
          geometry Box {
            size 0.1 0.1 0.1
          }
        }
      ]
    }
    Transform {
      translation 0.04 0.03 -0.1
      rotation 1 0 0 -0.523595307179586
      scale 0.1 0.25 0.1
      children [
        Shape {
          appearance PBRAppearance {
            baseColor 1 0.721569 0.0745098
            roughness 1
            metalness 0
          }
          geometry Box {
            size 0.1 0.1 0.1
          }
        }
      ]
    }
    Transform {
      translation -0.04 0.03 -0.1
      rotation 1 0 0 -0.523595307179586
      scale 0.1 0.25 0.1
      children [
        Shape {
          appearance PBRAppearance {
            baseColor 1 0.721569 0.0745098
            roughness 1
            metalness 0
          }
          geometry Box {
            size 0.1 0.1 0.1
          }
        }
      ]
    }
    Transform {
      translation 0 0.041 -0.11
      scale 1.1 0.05 0.3
      children [
        Shape {
          appearance PBRAppearance {
            baseColor 1 0.721569 0.0745098
            roughness 1
            metalness 0
          }
          geometry Box {
            size 0.1 0.1 0.1
          }
        }
      ]
    }
    DEF Body Group {
      children [
        Shape {
          appearance PBRAppearance {
            transparency 1
          }
          geometry Box {
            size 0.1 0.05 0.2
          }
        }
      ]
    }
    GPS {
    }
    Compass {
    }
    HingeJoint {
      jointParameters HingeJointParameters {
        anchor 0.06 0 0.05
      }
      device [
        RotationalMotor {
          name "wheel_fl"
          maxVelocity 100
          maxTorque 100
        }
      ]
      endPoint Solid {
        translation 0.06 0 0.05
        rotation 7.846886473750622e-17 1 0 1.571707932926737
        children [
          DEF wheel Shape {
            appearance PBRAppearance {
              baseColor 0 0 0
              roughness 1
              metalness 0
            }
            geometry Cylinder {
              height 0.02
              radius 0.04
            }
          }
        ]
        name "solid(1)"
        boundingObject USE wheel
        physics Physics {
        }
      }
    }
    DistanceSensor {
      translation 0.045 0 0.1
      rotation 0 -1 0 0.785406
      children [
        Shape {
          appearance PBRAppearance {
            baseColor 0 1 1
            roughness 1
            metalness 0
          }
          geometry Box {
            size 0.01 0.01 0.01
          }
        }
      ]
      name "ds_left"
      lookupTable [
        0 0 0
        0.2 1000 0
      ]
      type "laser"
    }
    DistanceSensor {
      translation -0.045 0 0.1
      rotation 0 1 0 -2.3561953071795863
      children [
        Shape {
          appearance PBRAppearance {
            baseColor 0 1 1
            roughness 1
            metalness 0
          }
          geometry Box {
            size 0.01 0.01 0.01
          }
        }
      ]
      name "ds_right"
      lookupTable [
        0 0 0
        0.2 1000 0
      ]
      type "laser"
    }
    DistanceSensor {
      translation 0 0 0.1
      rotation 0 1 0 -1.57
      children [
        Shape {
          appearance PBRAppearance {
            baseColor 0 1 1
            roughness 1
            metalness 0
          }
          geometry Box {
            size 0.01 0.01 0.01
          }
        }
      ]
      name "ds_mid"
      lookupTable [
        0 0 0
        0.2 1000 0
      ]
      type "laser"
    }
    HingeJoint {
      jointParameters HingeJointParameters {
        anchor 0.06 0 -0.05
      }
      endPoint Solid {
        translation 0.06 0 -0.05
        rotation -3.923443192396346e-17 1 3.923443192396346e-17 1.57170795562085
        children [
          DEF wheel Shape {
            appearance PBRAppearance {
              baseColor 0 0 0
              roughness 1
              metalness 0
            }
            geometry Cylinder {
              height 0.02
              radius 0.04
            }
          }
        ]
        name "solid(2)"
        boundingObject USE wheel
        physics Physics {
        }
      }
    }
    HingeJoint {
      jointParameters HingeJointParameters {
        anchor -0.06 0 0.05
      }
      device [
        RotationalMotor {
          name "wheel_fr"
          maxVelocity 100
          maxTorque 100
        }
      ]
      endPoint Solid {
        translation -0.06 0 0.05
        rotation -5.88614467583233e-17 1 7.848192901109774e-17 1.571374732696555
        children [
          DEF wheel Shape {
            appearance PBRAppearance {
              baseColor 0 0 0
              roughness 1
              metalness 0
            }
            geometry Cylinder {
              height 0.02
              radius 0.04
            }
          }
        ]
        name "solid(3)"
        boundingObject USE wheel
        physics Physics {
        }
      }
    }
    HingeJoint {
      jointParameters HingeJointParameters {
        anchor -0.06 0 -0.05
      }
      endPoint Solid {
        translation -0.06 0 -0.05
        rotation 3.924096452972608e-17 1 9.81024113243152e-17 1.571374731463599
        children [
          DEF wheel Shape {
            appearance PBRAppearance {
              baseColor 0 0 0
              roughness 1
              metalness 0
            }
            geometry Cylinder {
              height 0.02
              radius 0.04
            }
          }
        ]
        name "solid(4)"
        boundingObject USE wheel
        physics Physics {
        }
      }
    }
  ]
  boundingObject USE Body
  physics Physics {
  }
  controller "robot_controller"
}
